Workbook

Sheet Dashboard
A1: Home Renovation — Project Dashboard
A2: Everything here updates from the Tasks sheet. Yellow cells are yours to fill in.
A4: Possession date | B4: 46330 | D4: Overdue items | E4: =COUNTIF(Tasks!S5:S500,"OVERDUE") -> 0
A5: Today | B5: =TODAY() -> 46315 | D5: Due in next 7 days | E5: =COUNTIF(Tasks!S5:S500,"Due this week") -> 0
A6: Days until possession | B6: =IF(B4-B5>0,B4-B5,"Moved in") -> 15 | D6: Overall progress | E6: =IFERROR(COUNTIFS(Tasks!Q5:Q500,0,Tasks!E5:E500,"Done")/COUNTIF(Tasks!Q5:Q500,0),0) -> 0
A8: Area | B8: Tasks | C8: Sub-tasks | D8: In Progress | E8: Done | F8: % Complete | G8: Next Due | H8: Budget ($) | I8: Est. Cost ($) | J8: Actual ($) | K8: Remaining Budget ($) | L8: Variance vs Est. ($)
A9: Admin & Possession | B9: =COUNTIFS(Tasks!$C$5:$C$500,$A9,Tasks!$B$5:$B$500,"",Tasks!$A$5:$A$500,"<>") -> 2 | C9: =COUNTIFS(Tasks!$C$5:$C$500,$A9,Tasks!$B$5:$B$500,"<>") -> 6 | D9: =COUNTIFS(Tasks!$C$5:$C$500,$A9,Tasks!$E$5:$E$500,"In Progress") -> 0 | E9: =COUNTIFS(Tasks!$C$5:$C$500,$A9,Tasks!$E$5:$E$500,"Done") -> 0 | F9: =IFERROR(COUNTIFS(Tasks!$C$5:$C$500,$A9,Tasks!$Q$5:$Q$500,0,Tasks!$E$5:$E$500,"Done")/COUNTIFS(Tasks!$C$5:$C$500,$A9,Tasks!$Q$5:$Q$500,0),0) -> 0 | G9: =IFERROR(IF(_xlfn.MINIFS(Tasks!$J$5:$J$500,Tasks!$C$5:$C$500,$A9,Tasks!$E$5:$E$500,"<>Done")=0,"",_xlfn.MINIFS(Tasks!$J$5:$J$500,Tasks!$C$5:$C$500,$A9,Tasks!$E$5:$E$500,"<>Done")),"") -> 46330 | I9: =SUMIFS(Tasks!$N$5:$N$500,Tasks!$C$5:$C$500,$A9,Tasks!$Q$5:$Q$500,0) -> 0 | J9: =SUMIFS(Tasks!$O$5:$O$500,Tasks!$C$5:$C$500,$A9,Tasks!$Q$5:$Q$500,0) -> 0 | K9: =IF(H9="","",H9-J9) | L9: =J9-I9 -> 0
A10: Mold Remediation | B10: =COUNTIFS(Tasks!$C$5:$C$500,$A10,Tasks!$B$5:$B$500,"",Tasks!$A$5:$A$500,"<>") -> 4 | C10: =COUNTIFS(Tasks!$C$5:$C$500,$A10,Tasks!$B$5:$B$500,"<>") -> 10 | D10: =COUNTIFS(Tasks!$C$5:$C$500,$A10,Tasks!$E$5:$E$500,"In Progress") -> 0 | E10: =COUNTIFS(Tasks!$C$5:$C$500,$A10,Tasks!$E$5:$E$500,"Done") -> 0 | F10: =IFERROR(COUNTIFS(Tasks!$C$5:$C$500,$A10,Tasks!$Q$5:$Q$500,0,Tasks!$E$5:$E$500,"Done")/COUNTIFS(Tasks!$C$5:$C$500,$A10,Tasks!$Q$5:$Q$500,0),0) -> 0 | G10: =IFERROR(IF(_xlfn.MINIFS(Tasks!$J$5:$J$500,Tasks!$C$5:$C$500,$A10,Tasks!$E$5:$E$500,"<>Done")=0,"",_xlfn.MINIFS(Tasks!$J$5:$J$500,Tasks!$C$5:$C$500,$A10,Tasks!$E$5:$E$500,"<>Done")),"") -> 46332 | I10: =SUMIFS(Tasks!$N$5:$N$500,Tasks!$C$5:$C$500,$A10,Tasks!$Q$5:$Q$500,0) -> 0 | J10: =SUMIFS(Tasks!$O$5:$O$500,Tasks!$C$5:$C$500,$A10,Tasks!$Q$5:$Q$500,0) -> 0 | K10: =IF(H10="","",H10-J10) | L10: =J10-I10 -> 0
A11: Electrical Rough-in | B11: =COUNTIFS(Tasks!$C$5:$C$500,$A11,Tasks!$B$5:$B$500,"",Tasks!$A$5:$A$500,"<>") -> 3 | C11: =COUNTIFS(Tasks!$C$5:$C$500,$A11,Tasks!$B$5:$B$500,"<>") -> 6 | D11: =COUNTIFS(Tasks!$C$5:$C$500,$A11,Tasks!$E$5:$E$500,"In Progress") -> 0 | E11: =COUNTIFS(Tasks!$C$5:$C$500,$A11,Tasks!$E$5:$E$500,"Done") -> 0 | F11: =IFERROR(COUNTIFS(Tasks!$C$5:$C$500,$A11,Tasks!$Q$5:$Q$500,0,Tasks!$E$5:$E$500,"Done")/COUNTIFS(Tasks!$C$5:$C$500,$A11,Tasks!$Q$5:$Q$500,0),0) -> 0 | G11: =IFERROR(IF(_xlfn.MINIFS(Tasks!$J$5:$J$500,Tasks!$C$5:$C$500,$A11,Tasks!$E$5:$E$500,"<>Done")=0,"",_xlfn.MINIFS(Tasks!$J$5:$J$500,Tasks!$C$5:$C$500,$A11,Tasks!$E$5:$E$500,"<>Done")),"") -> 46336 | I11: =SUMIFS(Tasks!$N$5:$N$500,Tasks!$C$5:$C$500,$A11,Tasks!$Q$5:$Q$500,0) -> 0 | J11: =SUMIFS(Tasks!$O$5:$O$500,Tasks!$C$5:$C$500,$A11,Tasks!$Q$5:$Q$500,0) -> 0 | K11: =IF(H11="","",H11-J11) | L11: =J11-I11 -> 0
A12: Networking | B12: =COUNTIFS(Tasks!$C$5:$C$500,$A12,Tasks!$B$5:$B$500,"",Tasks!$A$5:$A$500,"<>") -> 1 | C12: =COUNTIFS(Tasks!$C$5:$C$500,$A12,Tasks!$B$5:$B$500,"<>") -> 6 | D12: =COUNTIFS(Tasks!$C$5:$C$500,$A12,Tasks!$E$5:$E$500,"In Progress") -> 0 | E12: =COUNTIFS(Tasks!$C$5:$C$500,$A12,Tasks!$E$5:$E$500,"Done") -> 0 | F12: =IFERROR(COUNTIFS(Tasks!$C$5:$C$500,$A12,Tasks!$Q$5:$Q$500,0,Tasks!$E$5:$E$500,"Done")/COUNTIFS(Tasks!$C$5:$C$500,$A12,Tasks!$Q$5:$Q$500,0),0) -> 0 | G12: =IFERROR(IF(_xlfn.MINIFS(Tasks!$J$5:$J$500,Tasks!$C$5:$C$500,$A12,Tasks!$E$5:$E$500,"<>Done")=0,"",_xlfn.MINIFS(Tasks!$J$5:$J$500,Tasks!$C$5:$C$500,$A12,Tasks!$E$5:$E$500,"<>Done")),"") -> 46336 | I12: =SUMIFS(Tasks!$N$5:$N$500,Tasks!$C$5:$C$500,$A12,Tasks!$Q$5:$Q$500,0) -> 0 | J12: =SUMIFS(Tasks!$O$5:$O$500,Tasks!$C$5:$C$500,$A12,Tasks!$Q$5:$Q$500,0) -> 0 | K12: =IF(H12="","",H12-J12) | L12: =J12-I12 -> 0
A13: Security Cameras | B13: =COUNTIFS(Tasks!$C$5:$C$500,$A13,Tasks!$B$5:$B$500,"",Tasks!$A$5:$A$500,"<>") -> 1 | C13: =COUNTIFS(Tasks!$C$5:$C$500,$A13,Tasks!$B$5:$B$500,"<>") -> 4 | D13: =COUNTIFS(Tasks!$C$5:$C$500,$A13,Tasks!$E$5:$E$500,"In Progress") -> 0 | E13: =COUNTIFS(Tasks!$C$5:$C$500,$A13,Tasks!$E$5:$E$500,"Done") -> 0 | F13: =IFERROR(COUNTIFS(Tasks!$C$5:$C$500,$A13,Tasks!$Q$5:$Q$500,0,Tasks!$E$5:$E$500,"Done")/COUNTIFS(Tasks!$C$5:$C$500,$A13,Tasks!$Q$5:$Q$500,0),0) -> 0 | G13: =IFERROR(IF(_xlfn.MINIFS(Tasks!$J$5:$J$500,Tasks!$C$5:$C$500,$A13,Tasks!$E$5:$E$500,"<>Done")=0,"",_xlfn.MINIFS(Tasks!$J$5:$J$500,Tasks!$C$5:$C$500,$A13,Tasks!$E$5:$E$500,"<>Done")),"") -> 46336 | I13: =SUMIFS(Tasks!$N$5:$N$500,Tasks!$C$5:$C$500,$A13,Tasks!$Q$5:$Q$500,0) -> 0 | J13: =SUMIFS(Tasks!$O$5:$O$500,Tasks!$C$5:$C$500,$A13,Tasks!$Q$5:$Q$500,0) -> 0 | K13: =IF(H13="","",H13-J13) | L13: =J13-I13 -> 0
A14: Insulation | B14: =COUNTIFS(Tasks!$C$5:$C$500,$A14,Tasks!$B$5:$B$500,"",Tasks!$A$5:$A$500,"<>") -> 2 | C14: =COUNTIFS(Tasks!$C$5:$C$500,$A14,Tasks!$B$5:$B$500,"<>") -> 4 | D14: =COUNTIFS(Tasks!$C$5:$C$500,$A14,Tasks!$E$5:$E$500,"In Progress") -> 0 | E14: =COUNTIFS(Tasks!$C$5:$C$500,$A14,Tasks!$E$5:$E$500,"Done") -> 0 | F14: =IFERROR(COUNTIFS(Tasks!$C$5:$C$500,$A14,Tasks!$Q$5:$Q$500,0,Tasks!$E$5:$E$500,"Done")/COUNTIFS(Tasks!$C$5:$C$500,$A14,Tasks!$Q$5:$Q$500,0),0) -> 0 | G14: =IFERROR(IF(_xlfn.MINIFS(Tasks!$J$5:$J$500,Tasks!$C$5:$C$500,$A14,Tasks!$E$5:$E$500,"<>Done")=0,"",_xlfn.MINIFS(Tasks!$J$5:$J$500,Tasks!$C$5:$C$500,$A14,Tasks!$E$5:$E$500,"<>Done")),"") -> 46339 | I14: =SUMIFS(Tasks!$N$5:$N$500,Tasks!$C$5:$C$500,$A14,Tasks!$Q$5:$Q$500,0) -> 0 | J14: =SUMIFS(Tasks!$O$5:$O$500,Tasks!$C$5:$C$500,$A14,Tasks!$Q$5:$Q$500,0) -> 0 | K14: =IF(H14="","",H14-J14) | L14: =J14-I14 -> 0
A15: Lighting & Pot Lights | B15: =COUNTIFS(Tasks!$C$5:$C$500,$A15,Tasks!$B$5:$B$500,"",Tasks!$A$5:$A$500,"<>") -> 3 | C15: =COUNTIFS(Tasks!$C$5:$C$500,$A15,Tasks!$B$5:$B$500,"<>") -> 3 | D15: =COUNTIFS(Tasks!$C$5:$C$500,$A15,Tasks!$E$5:$E$500,"In Progress") -> 0 | E15: =COUNTIFS(Tasks!$C$5:$C$500,$A15,Tasks!$E$5:$E$500,"Done") -> 0 | F15: =IFERROR(COUNTIFS(Tasks!$C$5:$C$500,$A15,Tasks!$Q$5:$Q$500,0,Tasks!$E$5:$E$500,"Done")/COUNTIFS(Tasks!$C$5:$C$500,$A15,Tasks!$Q$5:$Q$500,0),0) -> 0 | G15: =IFERROR(IF(_xlfn.MINIFS(Tasks!$J$5:$J$500,Tasks!$C$5:$C$500,$A15,Tasks!$E$5:$E$500,"<>Done")=0,"",_xlfn.MINIFS(Tasks!$J$5:$J$500,Tasks!$C$5:$C$500,$A15,Tasks!$E$5:$E$500,"<>Done")),"") -> 46339 | I15: =SUMIFS(Tasks!$N$5:$N$500,Tasks!$C$5:$C$500,$A15,Tasks!$Q$5:$Q$500,0) -> 0 | J15: =SUMIFS(Tasks!$O$5:$O$500,Tasks!$C$5:$C$500,$A15,Tasks!$Q$5:$Q$500,0) -> 0 | K15: =IF(H15="","",H15-J15) | L15: =J15-I15 -> 0
A16: Kitchen | B16: =COUNTIFS(Tasks!$C$5:$C$500,$A16,Tasks!$B$5:$B$500,"",Tasks!$A$5:$A$500,"<>") -> 10 | C16: =COUNTIFS(Tasks!$C$5:$C$500,$A16,Tasks!$B$5:$B$500,"<>") -> 3 | D16: =COUNTIFS(Tasks!$C$5:$C$500,$A16,Tasks!$E$5:$E$500,"In Progress") -> 0 | E16: =COUNTIFS(Tasks!$C$5:$C$500,$A16,Tasks!$E$5:$E$500,"Done") -> 0 | F16: =IFERROR(COUNTIFS(Tasks!$C$5:$C$500,$A16,Tasks!$Q$5:$Q$500,0,Tasks!$E$5:$E$500,"Done")/COUNTIFS(Tasks!$C$5:$C$500,$A16,Tasks!$Q$5:$Q$500,0),0) -> 0 | G16: =IFERROR(IF(_xlfn.MINIFS(Tasks!$J$5:$J$500,Tasks!$C$5:$C$500,$A16,Tasks!$E$5:$E$500,"<>Done")=0,"",_xlfn.MINIFS(Tasks!$J$5:$J$500,Tasks!$C$5:$C$500,$A16,Tasks!$E$5:$E$500,"<>Done")),"") | I16: =SUMIFS(Tasks!$N$5:$N$500,Tasks!$C$5:$C$500,$A16,Tasks!$Q$5:$Q$500,0) -> 0 | J16: =SUMIFS(Tasks!$O$5:$O$500,Tasks!$C$5:$C$500,$A16,Tasks!$Q$5:$Q$500,0) -> 0 | K16: =IF(H16="","",H16-J16) | L16: =J16-I16 -> 0
A17: Laundry Room | B17: =COUNTIFS(Tasks!$C$5:$C$500,$A17,Tasks!$B$5:$B$500,"",Tasks!$A$5:$A$500,"<>") -> 7 | C17: =COUNTIFS(Tasks!$C$5:$C$500,$A17,Tasks!$B$5:$B$500,"<>") -> 0 | D17: =COUNTIFS(Tasks!$C$5:$C$500,$A17,Tasks!$E$5:$E$500,"In Progress") -> 0 | E17: =COUNTIFS(Tasks!$C$5:$C$500,$A17,Tasks!$E$5:$E$500,"Done") -> 0 | F17: =IFERROR(COUNTIFS(Tasks!$C$5:$C$500,$A17,Tasks!$Q$5:$Q$500,0,Tasks!$E$5:$E$500,"Done")/COUNTIFS(Tasks!$C$5:$C$500,$A17,Tasks!$Q$5:$Q$500,0),0) -> 0 | G17: =IFERROR(IF(_xlfn.MINIFS(Tasks!$J$5:$J$500,Tasks!$C$5:$C$500,$A17,Tasks!$E$5:$E$500,"<>Done")=0,"",_xlfn.MINIFS(Tasks!$J$5:$J$500,Tasks!$C$5:$C$500,$A17,Tasks!$E$5:$E$500,"<>Done")),"") | I17: =SUMIFS(Tasks!$N$5:$N$500,Tasks!$C$5:$C$500,$A17,Tasks!$Q$5:$Q$500,0) -> 0 | J17: =SUMIFS(Tasks!$O$5:$O$500,Tasks!$C$5:$C$500,$A17,Tasks!$Q$5:$Q$500,0) -> 0 | K17: =IF(H17="","",H17-J17) | L17: =J17-I17 -> 0
A18: Upstairs Bath 1 | B18: =COUNTIFS(Tasks!$C$5:$C$500,$A18,Tasks!$B$5:$B$500,"",Tasks!$A$5:$A$500,"<>") -> 8 | C18: =COUNTIFS(Tasks!$C$5:$C$500,$A18,Tasks!$B$5:$B$500,"<>") -> 0 | D18: =COUNTIFS(Tasks!$C$5:$C$500,$A18,Tasks!$E$5:$E$500,"In Progress") -> 0 | E18: =COUNTIFS(Tasks!$C$5:$C$500,$A18,Tasks!$E$5:$E$500,"Done") -> 0 | F18: =IFERROR(COUNTIFS(Tasks!$C$5:$C$500,$A18,Tasks!$Q$5:$Q$500,0,Tasks!$E$5:$E$500,"Done")/COUNTIFS(Tasks!$C$5:$C$500,$A18,Tasks!$Q$5:$Q$500,0),0) -> 0 | G18: =IFERROR(IF(_xlfn.MINIFS(Tasks!$J$5:$J$500,Tasks!$C$5:$C$500,$A18,Tasks!$E$5:$E$500,"<>Done")=0,"",_xlfn.MINIFS(Tasks!$J$5:$J$500,Tasks!$C$5:$C$500,$A18,Tasks!$E$5:$E$500,"<>Done")),"") | I18: =SUMIFS(Tasks!$N$5:$N$500,Tasks!$C$5:$C$500,$A18,Tasks!$Q$5:$Q$500,0) -> 0 | J18: =SUMIFS(Tasks!$O$5:$O$500,Tasks!$C$5:$C$500,$A18,Tasks!$Q$5:$Q$500,0) -> 0 | K18: =IF(H18="","",H18-J18) | L18: =J18-I18 -> 0
A19: Upstairs Bath 2 | B19: =COUNTIFS(Tasks!$C$5:$C$500,$A19,Tasks!$B$5:$B$500,"",Tasks!$A$5:$A$500,"<>") -> 8 | C19: =COUNTIFS(Tasks!$C$5:$C$500,$A19,Tasks!$B$5:$B$500,"<>") -> 0 | D19: =COUNTIFS(Tasks!$C$5:$C$500,$A19,Tasks!$E$5:$E$500,"In Progress") -> 0 | E19: =COUNTIFS(Tasks!$C$5:$C$500,$A19,Tasks!$E$5:$E$500,"Done") -> 0 | F19: =IFERROR(COUNTIFS(Tasks!$C$5:$C$500,$A19,Tasks!$Q$5:$Q$500,0,Tasks!$E$5:$E$500,"Done")/COUNTIFS(Tasks!$C$5:$C$500,$A19,Tasks!$Q$5:$Q$500,0),0) -> 0 | G19: =IFERROR(IF(_xlfn.MINIFS(Tasks!$J$5:$J$500,Tasks!$C$5:$C$500,$A19,Tasks!$E$5:$E$500,"<>Done")=0,"",_xlfn.MINIFS(Tasks!$J$5:$J$500,Tasks!$C$5:$C$500,$A19,Tasks!$E$5:$E$500,"<>Done")),"") | I19: =SUMIFS(Tasks!$N$5:$N$500,Tasks!$C$5:$C$500,$A19,Tasks!$Q$5:$Q$500,0) -> 0 | J19: =SUMIFS(Tasks!$O$5:$O$500,Tasks!$C$5:$C$500,$A19,Tasks!$Q$5:$Q$500,0) -> 0 | K19: =IF(H19="","",H19-J19) | L19: =J19-I19 -> 0
A20: Trim & Doors (Whole House) | B20: =COUNTIFS(Tasks!$C$5:$C$500,$A20,Tasks!$B$5:$B$500,"",Tasks!$A$5:$A$500,"<>") -> 6 | C20: =COUNTIFS(Tasks!$C$5:$C$500,$A20,Tasks!$B$5:$B$500,"<>") -> 0 | D20: =COUNTIFS(Tasks!$C$5:$C$500,$A20,Tasks!$E$5:$E$500,"In Progress") -> 0 | E20: =COUNTIFS(Tasks!$C$5:$C$500,$A20,Tasks!$E$5:$E$500,"Done") -> 0 | F20: =IFERROR(COUNTIFS(Tasks!$C$5:$C$500,$A20,Tasks!$Q$5:$Q$500,0,Tasks!$E$5:$E$500,"Done")/COUNTIFS(Tasks!$C$5:$C$500,$A20,Tasks!$Q$5:$Q$500,0),0) -> 0 | G20: =IFERROR(IF(_xlfn.MINIFS(Tasks!$J$5:$J$500,Tasks!$C$5:$C$500,$A20,Tasks!$E$5:$E$500,"<>Done")=0,"",_xlfn.MINIFS(Tasks!$J$5:$J$500,Tasks!$C$5:$C$500,$A20,Tasks!$E$5:$E$500,"<>Done")),"") | I20: =SUMIFS(Tasks!$N$5:$N$500,Tasks!$C$5:$C$500,$A20,Tasks!$Q$5:$Q$500,0) -> 0 | J20: =SUMIFS(Tasks!$O$5:$O$500,Tasks!$C$5:$C$500,$A20,Tasks!$Q$5:$Q$500,0) -> 0 | K20: =IF(H20="","",H20-J20) | L20: =J20-I20 -> 0
A21: Other | B21: =COUNTIFS(Tasks!$C$5:$C$500,$A21,Tasks!$B$5:$B$500,"",Tasks!$A$5:$A$500,"<>") -> 0 | C21: =COUNTIFS(Tasks!$C$5:$C$500,$A21,Tasks!$B$5:$B$500,"<>") -> 0 | D21: =COUNTIFS(Tasks!$C$5:$C$500,$A21,Tasks!$E$5:$E$500,"In Progress") -> 0 | E21: =COUNTIFS(Tasks!$C$5:$C$500,$A21,Tasks!$E$5:$E$500,"Done") -> 0 | F21: =IFERROR(COUNTIFS(Tasks!$C$5:$C$500,$A21,Tasks!$Q$5:$Q$500,0,Tasks!$E$5:$E$500,"Done")/COUNTIFS(Tasks!$C$5:$C$500,$A21,Tasks!$Q$5:$Q$500,0),0) -> 0 | G21: =IFERROR(IF(_xlfn.MINIFS(Tasks!$J$5:$J$500,Tasks!$C$5:$C$500,$A21,Tasks!$E$5:$E$500,"<>Done")=0,"",_xlfn.MINIFS(Tasks!$J$5:$J$500,Tasks!$C$5:$C$500,$A21,Tasks!$E$5:$E$500,"<>Done")),"") | I21: =SUMIFS(Tasks!$N$5:$N$500,Tasks!$C$5:$C$500,$A21,Tasks!$Q$5:$Q$500,0) -> 0 | J21: =SUMIFS(Tasks!$O$5:$O$500,Tasks!$C$5:$C$500,$A21,Tasks!$Q$5:$Q$500,0) -> 0 | K21: =IF(H21="","",H21-J21) | L21: =J21-I21 -> 0
A22: TOTAL | B22: =SUM(B9:B21) -> 55 | C22: =SUM(C9:C21) -> 42 | D22: =SUM(D9:D21) -> 0 | E22: =SUM(E9:E21) -> 0 | F22: =E6 -> 0 | G22: =IFERROR(IF(MIN(G9:G21)=0,"",MIN(G9:G21)),"") -> 46330 | H22: =SUM(H9:H21) -> 0 | I22: =SUM(I9:I21) -> 0 | J22: =SUM(J9:J21) -> 0 | K22: =H22-J22 -> 0 | L22: =J22-I22 -> 0
A24: Recommended order of work
A25: 1. Mold assessment → remediation → clearance test (fix the moisture source, not just the mold).
A26: 2. While the attic is open: all ceiling wiring — pot lights, bath fans, Cat6 drops, Wi-Fi APs, camera PoE runs — then electrical rough-in inspection.
A27: 3. Insulation goes in only after wiring is done and inspected (attic first, then basement walls).
A28: 4. Rough-in plumbing/electrical for kitchen, laundry & baths → drywall → tile, cabinets, flooring.
A29: 5. Paint, then trim & doors last so they aren't damaged by other trades.
A30: 6. Light fixtures, pot light trims, switches, cameras and network gear go in at the very end.

Sheet Tasks
A1: Renovation Task Tracker
A2: How to use: fill the white columns (A–O, T). Grey columns (P–S) calculate automatically. For a sub-task, give it its own ID (e.g. KIT-2.4) and put the parent's ID (KIT-2) in Parent ID. Enter costs on sub-tasks (or on tasks with no sub-tasks) so totals aren't double-counted. Dates are targets — adjust as quotes come in.
A4: ID | B4: Parent ID | C4: Area | D4: Task / Sub-task | E4: Status | F4: Priority | G4: Phase | H4: Assigned To | I4: Start | J4: Due | K4: Done Date | L4: Depends On | M4: Permit / Inspection? | N4: Est. Cost ($) | O4: Actual Cost ($) | P4: Variance ($) | Q4: # Sub-tasks | R4: Progress | S4: Flag | T4: Notes
A5: ADM-1 | C5: Admin & Possession | D5: Take possession of home | E5: Planned | F5: High | G5: 1 - Remediation | H5: DIY | I5: 46330 | J5: 46330 | M5: No | P5: =IF(OR(N5="",O5=""),"",O5-N5) | Q5: =IF(A5="","",COUNTIF($B$5:$B$500,A5)) -> 4 | R5: =IF(A5="","",IF(Q5>0,COUNTIFS($B$5:$B$500,A5,$E$5:$E$500,"Done")/Q5,IF(E5="Done",1,0))) -> 0 | S5: =IF(OR(A5="",E5="Done",J5=""),"",IF(J5<TODAY(),"OVERDUE",IF(J5-TODAY()<=7,"Due this week",""))) | T5: Key day: Wed Nov 4, 2026
A6: ADM-1.1 | B6: ADM-1 | C6: Admin & Possession | D6: Change locks / reprogram garage openers | E6: Not Started | F6: High | G6: 1 - Remediation | H6: DIY | I6: 46330 | J6: 46331 | M6: No | P6: =IF(OR(N6="",O6=""),"",O6-N6) | Q6: =IF(A6="","",COUNTIF($B$5:$B$500,A6)) -> 0 | R6: =IF(A6="","",IF(Q6>0,COUNTIFS($B$5:$B$500,A6,$E$5:$E$500,"Done")/Q6,IF(E6="Done",1,0))) -> 0 | S6: =IF(OR(A6="",E6="Done",J6=""),"",IF(J6<TODAY(),"OVERDUE",IF(J6-TODAY()<=7,"Due this week","")))
A7: ADM-1.2 | B7: ADM-1 | C7: Admin & Possession | D7: Transfer utilities & confirm home insurance start date | E7: Not Started | F7: High | G7: 1 - Remediation | H7: DIY | I7: 46330 | J7: 46330 | M7: No | P7: =IF(OR(N7="",O7=""),"",O7-N7) | Q7: =IF(A7="","",COUNTIF($B$5:$B$500,A7)) -> 0 | R7: =IF(A7="","",IF(Q7>0,COUNTIFS($B$5:$B$500,A7,$E$5:$E$500,"Done")/Q7,IF(E7="Done",1,0))) -> 0 | S7: =IF(OR(A7="",E7="Done",J7=""),"",IF(J7<TODAY(),"OVERDUE",IF(J7-TODAY()<=7,"Due this week",""))) | T7: Hydro, gas, water, internet
A8: ADM-1.3 | B8: ADM-1 | C8: Admin & Possession | D8: Photo/video document existing condition of every room | E8: Not Started | F8: Medium | G8: 1 - Remediation | H8: DIY | I8: 46330 | J8: 46331 | M8: No | P8: =IF(OR(N8="",O8=""),"",O8-N8) | Q8: =IF(A8="","",COUNTIF($B$5:$B$500,A8)) -> 0 | R8: =IF(A8="","",IF(Q8>0,COUNTIFS($B$5:$B$500,A8,$E$5:$E$500,"Done")/Q8,IF(E8="Done",1,0))) -> 0 | S8: =IF(OR(A8="",E8="Done",J8=""),"",IF(J8<TODAY(),"OVERDUE",IF(J8-TODAY()<=7,"Due this week",""))) | T8: Useful for insurance and before/after
A9: ADM-1.4 | B9: ADM-1 | C9: Admin & Possession | D9: Locate & label electrical panel; note amperage & free breaker slots | E9: Not Started | F9: High | G9: 1 - Remediation | H9: DIY | I9: 46330 | J9: 46332 | M9: No | P9: =IF(OR(N9="",O9=""),"",O9-N9) | Q9: =IF(A9="","",COUNTIF($B$5:$B$500,A9)) -> 0 | R9: =IF(A9="","",IF(Q9>0,COUNTIFS($B$5:$B$500,A9,$E$5:$E$500,"Done")/Q9,IF(E9="Done",1,0))) -> 0 | S9: =IF(OR(A9="",E9="Done",J9=""),"",IF(J9<TODAY(),"OVERDUE",IF(J9-TODAY()<=7,"Due this week",""))) | T9: Needed before planning pot lights & new circuits
A10: ADM-2 | C10: Admin & Possession | D10: Permits & approvals | E10: Not Started | F10: High | G10: 1 - Remediation | H10: DIY | I10: 46330 | J10: 46339 | M10: Check | P10: =IF(OR(N10="",O10=""),"",O10-N10) | Q10: =IF(A10="","",COUNTIF($B$5:$B$500,A10)) -> 2 | R10: =IF(A10="","",IF(Q10>0,COUNTIFS($B$5:$B$500,A10,$E$5:$E$500,"Done")/Q10,IF(E10="Done",1,0))) -> 0 | S10: =IF(OR(A10="",E10="Done",J10=""),"",IF(J10<TODAY(),"OVERDUE",IF(J10-TODAY()<=7,"Due this week","")))
A11: ADM-2.1 | B11: ADM-2 | C11: Admin & Possession | D11: Electrical permit / notification (ESA) for new circuits & pot lights | E11: Not Started | F11: High | G11: 2 - Rough-in | H11: Electrician | I11: 46335 | J11: 46339 | L11: ADM-1.4 | M11: Yes | P11: =IF(OR(N11="",O11=""),"",O11-N11) | Q11: =IF(A11="","",COUNTIF($B$5:$B$500,A11)) -> 0 | R11: =IF(A11="","",IF(Q11>0,COUNTIFS($B$5:$B$500,A11,$E$5:$E$500,"Done")/Q11,IF(E11="Done",1,0))) -> 0 | S11: =IF(OR(A11="",E11="Done",J11=""),"",IF(J11<TODAY(),"OVERDUE",IF(J11-TODAY()<=7,"Due this week",""))) | T11: Usually pulled by your licensed electrician
A12: ADM-2.2 | B12: ADM-2 | C12: Admin & Possession | D12: Check with City of Vaughan whether kitchen/bath/laundry plumbing changes need a building permit | E12: Not Started | F12: Medium | G12: 2 - Rough-in | H12: DIY | I12: 46335 | J12: 46346 | M12: Check | P12: =IF(OR(N12="",O12=""),"",O12-N12) | Q12: =IF(A12="","",COUNTIF($B$5:$B$500,A12)) -> 0 | R12: =IF(A12="","",IF(Q12>0,COUNTIFS($B$5:$B$500,A12,$E$5:$E$500,"Done")/Q12,IF(E12="Done",1,0))) -> 0 | S12: =IF(OR(A12="",E12="Done",J12=""),"",IF(J12<TODAY(),"OVERDUE",IF(J12-TODAY()<=7,"Due this week","")))
A13: MOLD-1 | C13: Mold Remediation | D13: Mold assessment & quotes | E13: Planned | F13: High | G13: 1 - Remediation | H13: Remediation Co. | I13: 46330 | J13: 46332 | L13: ADM-1 | M13: No | P13: =IF(OR(N13="",O13=""),"",O13-N13) | Q13: =IF(A13="","",COUNTIF($B$5:$B$500,A13)) -> 3 | R13: =IF(A13="","",IF(Q13>0,COUNTIFS($B$5:$B$500,A13,$E$5:$E$500,"Done")/Q13,IF(E13="Done",1,0))) -> 0 | S13: =IF(OR(A13="",E13="Done",J13=""),"",IF(J13<TODAY(),"OVERDUE",IF(J13-TODAY()<=7,"Due this week","")))
A14: MOLD-1.1 | B14: MOLD-1 | C14: Mold Remediation | D14: Get 2–3 remediation quotes (attic + basement scope) | E14: Not Started | F14: High | G14: 1 - Remediation | H14: DIY | I14: 46330 | J14: 46332 | M14: No | P14: =IF(OR(N14="",O14=""),"",O14-N14) | Q14: =IF(A14="","",COUNTIF($B$5:$B$500,A14)) -> 0 | R14: =IF(A14="","",IF(Q14>0,COUNTIFS($B$5:$B$500,A14,$E$5:$E$500,"Done")/Q14,IF(E14="Done",1,0))) -> 0 | S14: =IF(OR(A14="",E14="Done",J14=""),"",IF(J14<TODAY(),"OVERDUE",IF(J14-TODAY()<=7,"Due this week",""))) | T14: Can line up site visits before Nov 4 if seller allows
A15: MOLD-1.2 | B15: MOLD-1 | C15: Mold Remediation | D15: Identify moisture source in attic (bath fans venting into attic, ventilation, roof leak) | E15: Not Started | F15: High | G15: 1 - Remediation | H15: Remediation Co. | I15: 46330 | J15: 46332 | M15: No | P15: =IF(OR(N15="",O15=""),"",O15-N15) | Q15: =IF(A15="","",COUNTIF($B$5:$B$500,A15)) -> 0 | R15: =IF(A15="","",IF(Q15>0,COUNTIFS($B$5:$B$500,A15,$E$5:$E$500,"Done")/Q15,IF(E15="Done",1,0))) -> 0 | S15: =IF(OR(A15="",E15="Done",J15=""),"",IF(J15<TODAY(),"OVERDUE",IF(J15-TODAY()<=7,"Due this week",""))) | T15: Fix the cause or mold returns
A16: MOLD-1.3 | B16: MOLD-1 | C16: Mold Remediation | D16: Identify moisture source in basement (grading, foundation cracks, humidity, sump) | E16: Not Started | F16: High | G16: 1 - Remediation | H16: Remediation Co. | I16: 46330 | J16: 46332 | M16: No | P16: =IF(OR(N16="",O16=""),"",O16-N16) | Q16: =IF(A16="","",COUNTIF($B$5:$B$500,A16)) -> 0 | R16: =IF(A16="","",IF(Q16>0,COUNTIFS($B$5:$B$500,A16,$E$5:$E$500,"Done")/Q16,IF(E16="Done",1,0))) -> 0 | S16: =IF(OR(A16="",E16="Done",J16=""),"",IF(J16<TODAY(),"OVERDUE",IF(J16-TODAY()<=7,"Due this week","")))
A17: MOLD-2 | C17: Mold Remediation | D17: Attic mold remediation | E17: Not Started | F17: High | G17: 1 - Remediation | H17: Remediation Co. | I17: 46335 | J17: 46339 | L17: MOLD-1 | M17: No | P17: =IF(OR(N17="",O17=""),"",O17-N17) | Q17: =IF(A17="","",COUNTIF($B$5:$B$500,A17)) -> 4 | R17: =IF(A17="","",IF(Q17>0,COUNTIFS($B$5:$B$500,A17,$E$5:$E$500,"Done")/Q17,IF(E17="Done",1,0))) -> 0 | S17: =IF(OR(A17="",E17="Done",J17=""),"",IF(J17<TODAY(),"OVERDUE",IF(J17-TODAY()<=7,"Due this week","")))
A18: MOLD-2.1 | B18: MOLD-2 | C18: Mold Remediation | D18: Set up containment & negative air | E18: Not Started | F18: High | G18: 1 - Remediation | H18: Remediation Co. | I18: 46335 | J18: 46335 | M18: No | P18: =IF(OR(N18="",O18=""),"",O18-N18) | Q18: =IF(A18="","",COUNTIF($B$5:$B$500,A18)) -> 0 | R18: =IF(A18="","",IF(Q18>0,COUNTIFS($B$5:$B$500,A18,$E$5:$E$500,"Done")/Q18,IF(E18="Done",1,0))) -> 0 | S18: =IF(OR(A18="",E18="Done",J18=""),"",IF(J18<TODAY(),"OVERDUE",IF(J18-TODAY()<=7,"Due this week","")))
A19: MOLD-2.2 | B19: MOLD-2 | C19: Mold Remediation | D19: Remove contaminated insulation | E19: Not Started | F19: High | G19: 1 - Remediation | H19: Remediation Co. | I19: 46335 | J19: 46336 | M19: No | P19: =IF(OR(N19="",O19=""),"",O19-N19) | Q19: =IF(A19="","",COUNTIF($B$5:$B$500,A19)) -> 0 | R19: =IF(A19="","",IF(Q19>0,COUNTIFS($B$5:$B$500,A19,$E$5:$E$500,"Done")/Q19,IF(E19="Done",1,0))) -> 0 | S19: =IF(OR(A19="",E19="Done",J19=""),"",IF(J19<TODAY(),"OVERDUE",IF(J19-TODAY()<=7,"Due this week",""))) | T19: Attic will be open — best window for wiring runs
A20: MOLD-2.3 | B20: MOLD-2 | C20: Mold Remediation | D20: HEPA vacuum, treat & seal roof sheathing | E20: Not Started | F20: High | G20: 1 - Remediation | H20: Remediation Co. | I20: 46336 | J20: 46338 | M20: No | P20: =IF(OR(N20="",O20=""),"",O20-N20) | Q20: =IF(A20="","",COUNTIF($B$5:$B$500,A20)) -> 0 | R20: =IF(A20="","",IF(Q20>0,COUNTIFS($B$5:$B$500,A20,$E$5:$E$500,"Done")/Q20,IF(E20="Done",1,0))) -> 0 | S20: =IF(OR(A20="",E20="Done",J20=""),"",IF(J20<TODAY(),"OVERDUE",IF(J20-TODAY()<=7,"Due this week","")))
A21: MOLD-2.4 | B21: MOLD-2 | C21: Mold Remediation | D21: Correct attic ventilation (baffles, vents, bath fans ducted outside) | E21: Not Started | F21: High | G21: 1 - Remediation | H21: Contractor | I21: 46338 | J21: 46339 | L21: MOLD-1.2 | M21: No | P21: =IF(OR(N21="",O21=""),"",O21-N21) | Q21: =IF(A21="","",COUNTIF($B$5:$B$500,A21)) -> 0 | R21: =IF(A21="","",IF(Q21>0,COUNTIFS($B$5:$B$500,A21,$E$5:$E$500,"Done")/Q21,IF(E21="Done",1,0))) -> 0 | S21: =IF(OR(A21="",E21="Done",J21=""),"",IF(J21<TODAY(),"OVERDUE",IF(J21-TODAY()<=7,"Due this week","")))
A22: MOLD-3 | C22: Mold Remediation | D22: Basement mold remediation | E22: Not Started | F22: High | G22: 1 - Remediation | H22: Remediation Co. | I22: 46335 | J22: 46339 | L22: MOLD-1 | M22: No | P22: =IF(OR(N22="",O22=""),"",O22-N22) | Q22: =IF(A22="","",COUNTIF($B$5:$B$500,A22)) -> 3 | R22: =IF(A22="","",IF(Q22>0,COUNTIFS($B$5:$B$500,A22,$E$5:$E$500,"Done")/Q22,IF(E22="Done",1,0))) -> 0 | S22: =IF(OR(A22="",E22="Done",J22=""),"",IF(J22<TODAY(),"OVERDUE",IF(J22-TODAY()<=7,"Due this week","")))
A23: MOLD-3.1 | B23: MOLD-3 | C23: Mold Remediation | D23: Containment & removal of affected drywall / insulation | E23: Not Started | F23: High | G23: 1 - Remediation | H23: Remediation Co. | I23: 46335 | J23: 46337 | M23: No | P23: =IF(OR(N23="",O23=""),"",O23-N23) | Q23: =IF(A23="","",COUNTIF($B$5:$B$500,A23)) -> 0 | R23: =IF(A23="","",IF(Q23>0,COUNTIFS($B$5:$B$500,A23,$E$5:$E$500,"Done")/Q23,IF(E23="Done",1,0))) -> 0 | S23: =IF(OR(A23="",E23="Done",J23=""),"",IF(J23<TODAY(),"OVERDUE",IF(J23-TODAY()<=7,"Due this week","")))
A24: MOLD-3.2 | B24: MOLD-3 | C24: Mold Remediation | D24: Clean & treat framing / foundation walls | E24: Not Started | F24: High | G24: 1 - Remediation | H24: Remediation Co. | I24: 46337 | J24: 46339 | M24: No | P24: =IF(OR(N24="",O24=""),"",O24-N24) | Q24: =IF(A24="","",COUNTIF($B$5:$B$500,A24)) -> 0 | R24: =IF(A24="","",IF(Q24>0,COUNTIFS($B$5:$B$500,A24,$E$5:$E$500,"Done")/Q24,IF(E24="Done",1,0))) -> 0 | S24: =IF(OR(A24="",E24="Done",J24=""),"",IF(J24<TODAY(),"OVERDUE",IF(J24-TODAY()<=7,"Due this week","")))
A25: MOLD-3.3 | B25: MOLD-3 | C25: Mold Remediation | D25: Fix moisture source (dehumidifier, grading, crack repair) | E25: Not Started | F25: High | G25: 1 - Remediation | H25: Contractor | I25: 46337 | J25: 46346 | L25: MOLD-1.3 | M25: No | P25: =IF(OR(N25="",O25=""),"",O25-N25) | Q25: =IF(A25="","",COUNTIF($B$5:$B$500,A25)) -> 0 | R25: =IF(A25="","",IF(Q25>0,COUNTIFS($B$5:$B$500,A25,$E$5:$E$500,"Done")/Q25,IF(E25="Done",1,0))) -> 0 | S25: =IF(OR(A25="",E25="Done",J25=""),"",IF(J25<TODAY(),"OVERDUE",IF(J25-TODAY()<=7,"Due this week","")))
A26: MOLD-4 | C26: Mold Remediation | D26: Post-remediation clearance testing (attic & basement) | E26: Not Started | F26: High | G26: 1 - Remediation | H26: Remediation Co. | I26: 46342 | J26: 46342 | L26: MOLD-2, MOLD-3 | M26: No | P26: =IF(OR(N26="",O26=""),"",O26-N26) | Q26: =IF(A26="","",COUNTIF($B$5:$B$500,A26)) -> 0 | R26: =IF(A26="","",IF(Q26>0,COUNTIFS($B$5:$B$500,A26,$E$5:$E$500,"Done")/Q26,IF(E26="Done",1,0))) -> 0 | S26: =IF(OR(A26="",E26="Done",J26=""),"",IF(J26<TODAY(),"OVERDUE",IF(J26-TODAY()<=7,"Due this week",""))) | T26: Get clearance report before closing up with insulation
A27: ELEC-1 | C27: Electrical Rough-in | D27: Electrical plan | E27: Not Started | F27: High | G27: 2 - Rough-in | H27: Electrician | I27: 46331 | J27: 46339 | L27: ADM-1.4 | M27: Yes | P27: =IF(OR(N27="",O27=""),"",O27-N27) | Q27: =IF(A27="","",COUNTIF($B$5:$B$500,A27)) -> 3 | R27: =IF(A27="","",IF(Q27>0,COUNTIFS($B$5:$B$500,A27,$E$5:$E$500,"Done")/Q27,IF(E27="Done",1,0))) -> 0 | S27: =IF(OR(A27="",E27="Done",J27=""),"",IF(J27<TODAY(),"OVERDUE",IF(J27-TODAY()<=7,"Due this week","")))
A28: ELEC-1.1 | B28: ELEC-1 | C28: Electrical Rough-in | D28: Hire licensed electrician & get quote | E28: Not Started | F28: High | G28: 2 - Rough-in | H28: DIY | I28: 46331 | J28: 46336 | M28: No | P28: =IF(OR(N28="",O28=""),"",O28-N28) | Q28: =IF(A28="","",COUNTIF($B$5:$B$500,A28)) -> 0 | R28: =IF(A28="","",IF(Q28>0,COUNTIFS($B$5:$B$500,A28,$E$5:$E$500,"Done")/Q28,IF(E28="Done",1,0))) -> 0 | S28: =IF(OR(A28="",E28="Done",J28=""),"",IF(J28<TODAY(),"OVERDUE",IF(J28-TODAY()<=7,"Due this week","")))
A29: ELEC-1.2 | B29: ELEC-1 | C29: Electrical Rough-in | D29: Confirm panel capacity for new circuits (kitchen, laundry, lighting) | E29: Not Started | F29: High | G29: 2 - Rough-in | H29: Electrician | I29: 46335 | J29: 46339 | M29: No | P29: =IF(OR(N29="",O29=""),"",O29-N29) | Q29: =IF(A29="","",COUNTIF($B$5:$B$500,A29)) -> 0 | R29: =IF(A29="","",IF(Q29>0,COUNTIFS($B$5:$B$500,A29,$E$5:$E$500,"Done")/Q29,IF(E29="Done",1,0))) -> 0 | S29: =IF(OR(A29="",E29="Done",J29=""),"",IF(J29<TODAY(),"OVERDUE",IF(J29-TODAY()<=7,"Due this week",""))) | T29: May need panel upgrade
A30: ELEC-1.3 | B30: ELEC-1 | C30: Electrical Rough-in | D30: Mark room-by-room layout (pot lights, switches, outlets, fans) | E30: Not Started | F30: High | G30: 2 - Rough-in | H30: DIY | I30: 46331 | J30: 46339 | L30: LGT-1 | M30: No | P30: =IF(OR(N30="",O30=""),"",O30-N30) | Q30: =IF(A30="","",COUNTIF($B$5:$B$500,A30)) -> 0 | R30: =IF(A30="","",IF(Q30>0,COUNTIFS($B$5:$B$500,A30,$E$5:$E$500,"Done")/Q30,IF(E30="Done",1,0))) -> 0 | S30: =IF(OR(A30="",E30="Done",J30=""),"",IF(J30<TODAY(),"OVERDUE",IF(J30-TODAY()<=7,"Due this week","")))
A31: ELEC-2 | C31: Electrical Rough-in | D31: Attic wiring rough-in (before insulation) | E31: Not Started | F31: High | G31: 2 - Rough-in | H31: Electrician | I31: 46343 | J31: 46346 | L31: MOLD-4 | M31: Yes | P31: =IF(OR(N31="",O31=""),"",O31-N31) | Q31: =IF(A31="","",COUNTIF($B$5:$B$500,A31)) -> 3 | R31: =IF(A31="","",IF(Q31>0,COUNTIFS($B$5:$B$500,A31,$E$5:$E$500,"Done")/Q31,IF(E31="Done",1,0))) -> 0 | S31: =IF(OR(A31="",E31="Done",J31=""),"",IF(J31<TODAY(),"OVERDUE",IF(J31-TODAY()<=7,"Due this week",""))) | T31: Ceiling runs for upstairs pot lights & bath fans
A32: ELEC-2.1 | B32: ELEC-2 | C32: Electrical Rough-in | D32: Run upstairs pot light circuits & switch legs | E32: Not Started | F32: High | G32: 2 - Rough-in | H32: Electrician | I32: 46343 | J32: 46345 | M32: Yes | P32: =IF(OR(N32="",O32=""),"",O32-N32) | Q32: =IF(A32="","",COUNTIF($B$5:$B$500,A32)) -> 0 | R32: =IF(A32="","",IF(Q32>0,COUNTIFS($B$5:$B$500,A32,$E$5:$E$500,"Done")/Q32,IF(E32="Done",1,0))) -> 0 | S32: =IF(OR(A32="",E32="Done",J32=""),"",IF(J32<TODAY(),"OVERDUE",IF(J32-TODAY()<=7,"Due this week",""))) | T32: Use IC-rated, airtight fixtures under insulation
A33: ELEC-2.2 | B33: ELEC-2 | C33: Electrical Rough-in | D33: Wire bathroom exhaust fans (both upstairs baths) | E33: Not Started | F33: High | G33: 2 - Rough-in | H33: Electrician | I33: 46344 | J33: 46345 | M33: Yes | P33: =IF(OR(N33="",O33=""),"",O33-N33) | Q33: =IF(A33="","",COUNTIF($B$5:$B$500,A33)) -> 0 | R33: =IF(A33="","",IF(Q33>0,COUNTIFS($B$5:$B$500,A33,$E$5:$E$500,"Done")/Q33,IF(E33="Done",1,0))) -> 0 | S33: =IF(OR(A33="",E33="Done",J33=""),"",IF(J33<TODAY(),"OVERDUE",IF(J33-TODAY()<=7,"Due this week","")))
A34: ELEC-2.3 | B34: ELEC-2 | C34: Electrical Rough-in | D34: Rough-in inspection | E34: Not Started | F34: High | G34: 2 - Rough-in | H34: Electrician | I34: 46349 | J34: 46349 | L34: ELEC-2.1, ELEC-2.2 | M34: Yes | P34: =IF(OR(N34="",O34=""),"",O34-N34) | Q34: =IF(A34="","",COUNTIF($B$5:$B$500,A34)) -> 0 | R34: =IF(A34="","",IF(Q34>0,COUNTIFS($B$5:$B$500,A34,$E$5:$E$500,"Done")/Q34,IF(E34="Done",1,0))) -> 0 | S34: =IF(OR(A34="",E34="Done",J34=""),"",IF(J34<TODAY(),"OVERDUE",IF(J34-TODAY()<=7,"Due this week",""))) | T34: Must pass before insulation covers wiring
A35: ELEC-3 | C35: Electrical Rough-in | D35: Basement wiring rough-in (while walls are open) | E35: Not Started | F35: Medium | G35: 2 - Rough-in | H35: Electrician | I35: 46343 | J35: 46353 | L35: MOLD-4 | M35: Yes | P35: =IF(OR(N35="",O35=""),"",O35-N35) | Q35: =IF(A35="","",COUNTIF($B$5:$B$500,A35)) -> 0 | R35: =IF(A35="","",IF(Q35>0,COUNTIFS($B$5:$B$500,A35,$E$5:$E$500,"Done")/Q35,IF(E35="Done",1,0))) -> 0 | S35: =IF(OR(A35="",E35="Done",J35=""),"",IF(J35<TODAY(),"OVERDUE",IF(J35-TODAY()<=7,"Due this week","")))
A36: NET-1 | C36: Networking | D36: Whole-home network wiring | E36: Not Started | F36: High | G36: 2 - Rough-in | H36: Low-Voltage / AV | I36: 46331 | J36: 46346 | M36: No | P36: =IF(OR(N36="",O36=""),"",O36-N36) | Q36: =IF(A36="","",COUNTIF($B$5:$B$500,A36)) -> 6 | R36: =IF(A36="","",IF(Q36>0,COUNTIFS($B$5:$B$500,A36,$E$5:$E$500,"Done")/Q36,IF(E36="Done",1,0))) -> 0 | S36: =IF(OR(A36="",E36="Done",J36=""),"",IF(J36<TODAY(),"OVERDUE",IF(J36-TODAY()<=7,"Due this week","")))
A37: NET-1.1 | B37: NET-1 | C37: Networking | D37: Pick network/rack location (often basement utility room) | E37: Not Started | F37: High | G37: 2 - Rough-in | H37: DIY | I37: 46331 | J37: 46336 | M37: No | P37: =IF(OR(N37="",O37=""),"",O37-N37) | Q37: =IF(A37="","",COUNTIF($B$5:$B$500,A37)) -> 0 | R37: =IF(A37="","",IF(Q37>0,COUNTIFS($B$5:$B$500,A37,$E$5:$E$500,"Done")/Q37,IF(E37="Done",1,0))) -> 0 | S37: =IF(OR(A37="",E37="Done",J37=""),"",IF(J37<TODAY(),"OVERDUE",IF(J37-TODAY()<=7,"Due this week","")))
A38: NET-1.2 | B38: NET-1 | C38: Networking | D38: List Cat6 drops per room (TVs, offices, desks) | E38: Not Started | F38: High | G38: 2 - Rough-in | H38: DIY | I38: 46331 | J38: 46336 | M38: No | P38: =IF(OR(N38="",O38=""),"",O38-N38) | Q38: =IF(A38="","",COUNTIF($B$5:$B$500,A38)) -> 0 | R38: =IF(A38="","",IF(Q38>0,COUNTIFS($B$5:$B$500,A38,$E$5:$E$500,"Done")/Q38,IF(E38="Done",1,0))) -> 0 | S38: =IF(OR(A38="",E38="Done",J38=""),"",IF(J38<TODAY(),"OVERDUE",IF(J38-TODAY()<=7,"Due this week","")))
A39: NET-1.3 | B39: NET-1 | C39: Networking | D39: Plan ceiling Wi-Fi access point locations | E39: Not Started | F39: Medium | G39: 2 - Rough-in | H39: DIY | I39: 46331 | J39: 46336 | M39: No | P39: =IF(OR(N39="",O39=""),"",O39-N39) | Q39: =IF(A39="","",COUNTIF($B$5:$B$500,A39)) -> 0 | R39: =IF(A39="","",IF(Q39>0,COUNTIFS($B$5:$B$500,A39,$E$5:$E$500,"Done")/Q39,IF(E39="Done",1,0))) -> 0 | S39: =IF(OR(A39="",E39="Done",J39=""),"",IF(J39<TODAY(),"OVERDUE",IF(J39-TODAY()<=7,"Due this week","")))
A40: NET-1.4 | B40: NET-1 | C40: Networking | D40: Pull Cat6 through attic to upstairs rooms & APs | E40: Not Started | F40: High | G40: 2 - Rough-in | H40: Low-Voltage / AV | I40: 46343 | J40: 46346 | L40: MOLD-4 | M40: No | P40: =IF(OR(N40="",O40=""),"",O40-N40) | Q40: =IF(A40="","",COUNTIF($B$5:$B$500,A40)) -> 0 | R40: =IF(A40="","",IF(Q40>0,COUNTIFS($B$5:$B$500,A40,$E$5:$E$500,"Done")/Q40,IF(E40="Done",1,0))) -> 0 | S40: =IF(OR(A40="",E40="Done",J40=""),"",IF(J40<TODAY(),"OVERDUE",IF(J40-TODAY()<=7,"Due this week",""))) | T40: Do while attic insulation is out
A41: NET-1.5 | B41: NET-1 | C41: Networking | D41: Run conduit / pull strings for future runs | E41: Not Started | F41: Low | G41: 2 - Rough-in | H41: Low-Voltage / AV | I41: 46343 | J41: 46346 | M41: No | P41: =IF(OR(N41="",O41=""),"",O41-N41) | Q41: =IF(A41="","",COUNTIF($B$5:$B$500,A41)) -> 0 | R41: =IF(A41="","",IF(Q41>0,COUNTIFS($B$5:$B$500,A41,$E$5:$E$500,"Done")/Q41,IF(E41="Done",1,0))) -> 0 | S41: =IF(OR(A41="",E41="Done",J41=""),"",IF(J41<TODAY(),"OVERDUE",IF(J41-TODAY()<=7,"Due this week","")))
...

Sheet Contacts & Quotes
A1: Contractors, Contacts & Quotes
A2: Row 4 is an example — overwrite or delete it.
A3: Name | B3: Company | C3: Trade | D3: Phone | E3: Email | F3: Area(s) | G3: Quote ($) | H3: Quote Date | I3: Hired? | J3: Start Date | K3: Notes
A4: Jane Smith | B4: ABC Mold Solutions | C4: Remediation Co. | D4: (905) 555-0100 | E4: jane@example.com | F4: Attic, Basement | G4: 6500 | H4: 46323 | I4: No | K4: Example row — includes air testing

Sheet Lists
A1: Areas | B1: Status | C1: Priority | D1: Phase | E1: Assigned To | F1: Permit? | H1: Add new options at the bottom of any column (dropdowns read down to row 40).
A2: Admin & Possession | B2: Not Started | C2: High | D2: 1 - Remediation | E2: DIY | F2: Yes
A3: Mold Remediation | B3: Planned | C3: Medium | D3: 2 - Rough-in | E3: Contractor | F3: No
A4: Electrical Rough-in | B4: In Progress | C4: Low | D4: 3 - Insulation & Drywall | E4: Electrician | F4: Check
A5: Networking | B5: Waiting (Trade/Materials) | D5: 4 - Finishes | E5: Plumber
A6: Security Cameras | B6: On Hold | D6: 5 - Trim & Paint | E6: Remediation Co.
A7: Insulation | B7: Done | D7: 6 - Fixtures & Devices | E7: Insulation Co.
A8: Lighting & Pot Lights | E8: Low-Voltage / AV
A9: Kitchen | E9: TBD
A10: Laundry Room
A11: Upstairs Bath 1
A12: Upstairs Bath 2
A13: Trim & Doors (Whole House)
A14: Other
